Workbook

Sheet EDT
A2: Matriz Estructura de descomposición de tareas EDT
A4: Etapas | B4: DIAS | C4: HORAS POR ACTIVIDAD O ENTREGABLE | J4: DICCIONARIO EDT
A5: Fase de Planificación | B5: 18 | C5: Jefe de Proyecto | D5: Analista Programador | E5: DBA | F5: QA | G5: Diseñador | I5: SIGLA | J5: ROL ACTOR | K5: NOMBRE ACTOR
A6: Acta de Constitución de proyecto | B6: 3 | C6: 20 | D6: 4 | E6: 0 | F6: 0 | G6: 0 | I6: JP | J6: Jefe de Proyecto | K6: Luis Gonzalez
A7: Aprobación del Acta | B7: 1 | C7: 8 | D7: 0 | E7: 0 | F7: 0 | G7: 0 | I7: AP | J7: Analista Programador | K7: Javier Rodriguez
A8: Definición de requerimientos Generales | B8: 3 | C8: 12 | D8: 12 | E8: 0 | F8: 0 | G8: 0 | I8: DBA | J8: Desarrollador BD | K8: Martin Guerrero
A9: Organización del equipo | B9: 1 | C9: 8 | D9: 0 | E9: 0 | F9: 0 | G9: 0 | I9: QA | J9: Calidad Y Testing | K9: Allison Rubio
A10: Levantamiento de problemáticas y caso de negocio | B10: 3 | C10: 16 | D10: 8 | E10: 0 | F10: 0 | G10: 0 | I10: DI | J10: Diseñador | K10: Sebastian Rojas
A11: Definición de objetivos generales y específicos | B11: 2 | C11: 12 | D11: 4 | E11: 0 | F11: 0 | G11: 0
A12: Especificación de alcance y requerimientos funcionales | B12: 5 | C12: 20 | D12: 20 | E12: 0 | F12: 0 | G12: 0
A13: Fase de Análisis y diseño | B13: 20 | C13: Jefe de Proyecto | D13: Analista Programador | E13: DBA | F13: QA | G13: Diseñador
A14: Captura de requerimientos específicos | B14: 3 | C14: 8 | D14: 16 | E14: 0 | F14: 0 | G14: 0
A15: Documento de arquitectura SW | B15: 3 | C15: 4 | D15: 20 | E15: 0 | F15: 0 | G15: 0
A16: Documento de casos de uso | B16: 3 | C16: 4 | D16: 20 | E16: 0 | F16: 0 | G16: 0
A17: Prototipos | B17: 2 | C17: 0 | D17: 4 | E17: 0 | F17: 0 | G17: 12
A18: Propuesta ERS | B18: 3 | C18: 10 | D18: 14 | E18: 0 | F18: 0 | G18: 0
A19: Diseño UI/UX App Móvil Dueños de Mascotas | B19: 3 | C19: 0 | D19: 0 | E19: 0 | F19: 0 | G19: 24
A20: Diseño UI/UX Web Tiendas, Clínicas y Panel Admin | B20: 3 | C20: 0 | D20: 0 | E20: 0 | F20: 0 | G20: 24
A21: Fase de Desarrollo | B21: 46 | C21: Jefe de Proyecto | D21: Analista Programador | E21: DBA | F21: QA | G21: Diseñador
A22: Implementación ambiente de desarrollo | B22: 2 | C22: 2 | D22: 16 | E22: 8 | F22: 0 | G22: 0
A23: Creacion de los script de tablas base de datos | B23: 3 | C23: 0 | D23: 8 | E23: 24 | F23: 0 | G23: 0
A24: Creacion de los script de consultas PL/SQL | B24: 4 | C24: 0 | D24: 8 | E24: 32 | F24: 0 | G24: 0
A25: Módulo Registro, Perfil de Mascota e Historial Médico | B25: 4 | C25: 2 | D25: 32 | E25: 8 | F25: 0 | G25: 0
A26: Módulo Comparador de Precios y Catálogo de Productos | B26: 4 | C26: 0 | D26: 32 | E26: 8 | F26: 0 | G26: 0
A27: Sistema de Alertas de Precios y Recordatorios de Atenciones | B27: 3 | C27: 0 | D27: 24 | E27: 4 | F27: 0 | G27: 0
A28: Portal Clínicas: Fichas médicas, pacientes y gestión de horas | B28: 5 | C28: 2 | D28: 40 | E28: 8 | F28: 0 | G28: 4
A29: Portal Tiendas: Catálogo, actualización de stock y precios | B29: 4 | C29: 0 | D29: 32 | E29: 8 | F29: 0 | G29: 4
A30: Panel Administrativo General y Reportabilidad | B30: 4 | C30: 4 | D30: 32 | E30: 8 | F30: 0 | G30: 0
A31: Flujo de pedidos, asignación y seguimiento en tiempo real | B31: 5 | C31: 2 | D31: 40 | E31: 8 | F31: 0 | G31: 0
A32: App Repartidores: Control de rutas y carga de evidencia fotográfica | B32: 4 | C32: 0 | D32: 32 | E32: 4 | F32: 0 | G32: 4
A33: Desarrollo del algoritmo de detección de patrones (peso/salud) | B33: 5 | C33: 2 | D33: 40 | E33: 8 | F33: 0 | G33: 0
A34: Integración del sistema de alertas en la App y Panel | B34: 3 | C34: 2 | D34: 24 | E34: 4 | F34: 0 | G34: 0
A35: Modulos de Contratación | B35: 18
A36: Administrar Contratación. | B36: 2 | C36: 16 | D36: 0 | E36: 0 | F36: 0 | G36: 0
A37: Administrar Empleados. | B37: 2 | C37: 8 | D37: 8 | E37: 0 | F37: 0 | G37: 0
A38: Contratación de Personal Veterinario (Clínicas). | B38: 3 | C38: 12 | D38: 12 | E38: 0 | F38: 0 | G38: 0
A39: Contratación y Onboarding de Tiendas / Comercios. | B39: 3 | C39: 12 | D39: 12 | E39: 0 | F39: 0 | G39: 0
A40: Contratación de Repartidores / Fleet Onboarding. | B40: 3 | C40: 12 | D40: 12 | E40: 0 | F40: 0 | G40: 0
A41: Contratación del Equipo de Desarrollo y TI. | B41: 3 | C41: 16 | D41: 8 | E41: 0 | F41: 0 | G41: 0
A42: Contratación de Soporte y Atención al Cliente. | B42: 2 | C42: 12 | D42: 4 | E42: 0 | F42: 0 | G42: 0
...

Sheet Costos Fases
A2: SIGLA | B2: ROL | C2: NOMBRE | D2: VALOR HORA HH | E2: HORAS | F2: FASE PLANIFICACION | H2: COSTO POR HORA
A3: JP | B3: Jefe de Proyecto | C3: Luis Gonzalez Palma | D3: 12500 | E3: 13 | F3: =D3*E3 -> 162500 | H3: ROL | I3: NOMBRE | J3: COSTO x HORA | K3: Sueldo mes
A4: AP | B4: Analista Programador | C4: Javier Rodriguez | D4: 7340 | E4: =SUM(EDT!D6:D12) -> 48 | F4: =D4*E4 -> 352320 | H4: Jefe de Proyecto | I4: Luis Gonzalez Palma | J4: 12500 | K4: =2250000 -> 2250000
A5: DBA | B5: Desarrollador BD | C5: Martin Guerrero | D5: 13278 | E5: =SUM(EDT!E6:E12) -> 0 | F5: =D5*E5 -> 0 | H5: Analista Programador | I5: Javier Rodriguez | J5: 7340 | K5: =1321205 -> 1321205
A6: QA | B6: Calidad Y Testing | C6: Allison Rubio | D6: 10944 | E6: =SUM(EDT!F6:F12) -> 0 | F6: =D6*E6 -> 0 | H6: Administrador BD | I6: Martin Guerrero | J6: 13278 | K6: =2390000 -> 2390000
A7: DI | B7: Diseñador | C7: Sebastian Rojas | D7: 8444 | E7: =SUM(EDT!G6:G12) -> 0 | F7: =D7*E7 -> 0 | H7: Calidad Y Testing | I7: Allison Rubio | J7: 10944 | K7: =1970000 -> 1970000
B8: TOTAL FASE PLANIFICACION | F8: =SUM(F3:F7) -> 514820 | H8: Diseñador | I8: Sebastian Rojas | J8: 8444 | K8: =1520000 -> 1520000
A11: SIGLA | B11: ROL | C11: NOMBRE | D11: VALOR HORA HH | E11: HORAS | F11: FASE DISEÑO | H11: COSTO HH POR ROL
A12: JP | B12: Jefe de Proyecto | C12: Luis Gonzalez Palma | D12: 12500 | E12: =SUM(EDT!C14:C20) -> 26 | F12: =D12*E12 -> 325000 | H12: Jefe de Proyecto | I12: =F3+F12+F21+F30+F39 -> 3012500
A13: AP | B13: Analista Programador | C13: Javier Rodriguez | D13: 7340 | E13: =SUM(EDT!D14:D20) -> 74 | F13: =D13*E13 -> 543160 | H13: Analista Programador | I13: =F4+F13+F22+F31+F40 -> 8455680
A14: DBA | B14: Desarrollador BD | C14: Martin Guerrero | D14: 13278 | E14: =SUM(EDT!E14:E20) -> 0 | F14: =D14*E14 -> 0 | H14: Administrador BD | I14: =F5+F14+F23+F32+F41 -> 5895432
A15: QA | B15: Calidad Y Testing | C15: Allison Rubio | D15: 10944 | E15: =SUM(EDT!F14:F20) -> 0 | F15: =D15*E15 -> 0 | H15: Calidad Y Testing | I15: =F6+F15+F24+F33+F42 -> 1181952
A16: DI | B16: Diseñador | C16: Sebastian Rojas | D16: 8444 | E16: =SUM(EDT!G14:G20) -> 60 | F16: =D16*E16 -> 506640 | H16: Diseñador | I16: =F7+F16+F25+F34+F43 -> 1013280
B17: TOTAL FASE DISEÑO | F17: =SUM(F12:F16) -> 1374800 | H17: TOTAL HH | I17: =SUM(I12:I16) -> 19558844
A20: SIGLA | B20: ROL | C20: NOMBRE | D20: VALOR HORA HH | E20: HORAS | F20: FASE DESARROLLO | H20: COSTO POR FASE
A21: JP | B21: Jefe de Proyecto | C21: Luis Gonzalez Palma | D21: 12500 | E21: =SUM(EDT!C22:C34,EDT!C36:C42,EDT!C44:C47,EDT!C49:C51,EDT!C53:C55,EDT!C57:C58,EDT!C60:C62,EDT!C64:C65,EDT!C68:C70,EDT!C72:C74,EDT!C76:C77,EDT!C79,EDT!C81:C82,EDT!C85:C86,EDT!C88:C90,EDT!C92:C93,EDT!C95:C96) -> 150 | F21: =D21*E21 -> 1875000 | H21: Fase de Planificación | I21: =F8 -> 514820
A22: AP | B22: Analista Programador | C22: Javier Rodriguez | D22: 7340 | E22: =SUM(EDT!D23:D35,EDT!D37:D43,EDT!D45:D48,EDT!D50:D52,EDT!D54:D56,EDT!D58:D59,EDT!D61:D63,EDT!D65:D66,EDT!D69:D71,EDT!D73:D75,EDT!D77:D78,EDT!D80,EDT!D82:D83,EDT!D86:D87,EDT!D89:D91,EDT!D93:D94,EDT!D96:D97) -> 928 | F22: =D22*E22 -> 6811520 | H22: Fase de Análisis y Diseño | I22: =F17 -> 1374800
A23: DBA | B23: Desarrollador BD | C23: Martin Guerrero | D23: 13278 | E23: =SUM(EDT!E22:E34,EDT!E36:E42,EDT!E44:E47,EDT!E49:E51,EDT!E53:E55,EDT!E57:E58,EDT!E60:E62,EDT!E64:E65,EDT!E68:E70,EDT!E72:E74,EDT!E76:E77,EDT!E79,EDT!E81:E82,EDT!E85:E86,EDT!E88:E90,EDT!E92:E93,EDT!E95:E96) -> 372 | F23: =D23*E23 -> 4939416 | H23: Fase de Desarrollo | I23: =F26 -> 14065024
A24: QA | B24: Calidad Y Testing | C24: Allison Rubio | D24: 10944 | E24: =SUM(EDT!F22:F34,EDT!F36:F42,EDT!F44:F47,EDT!F49:F51,EDT!F53:F55,EDT!F57:F58,EDT!F60:F62,EDT!F64:F65,EDT!F68:F70,EDT!F72:F74,EDT!F76:F77,EDT!F79,EDT!F81:F82,EDT!F85:F86,EDT!F88:F90,EDT!F92:F93,EDT!F95:F96) -> 0 | F24: =D24*E24 -> 0 | H24: Fase de QA | I24: =F35 -> 1755480
A25: DI | B25: Diseñador | C25: Sebastian Rojas | D25: 8444 | E25: =SUM(EDT!G22:G34,EDT!G36:G42,EDT!G44:G47,EDT!G49:G51,EDT!G53:G55,EDT!G57:G58,EDT!G60:G62,EDT!G64:G65,EDT!G68:G70,EDT!G72:G74,EDT!G76:G77,EDT!G79,EDT!G81:G82,EDT!G85:G86,EDT!G88:G90,EDT!G92:G93,EDT!G95:G96) -> 52 | F25: =D25*E25 -> 439088 | H25: Fase de Implementación y Cierre | I25: =F44 -> 1848720
B26: TOTAL FASE DESARROLLO | F26: =SUM(F21:F25) -> 14065024 | H26: TOTAL HH FASES | I26: =SUM(I21:I25) -> 19558844
A29: SIGLA | B29: ROL | C29: NOMBRE | D29: VALOR HORA HH | E29: HORAS | F29: FASE PRUEBAS QA | H29: Margen | I29: 0.6
A30: JP | B30: Jefe de Proyecto | C30: Luis Gonzalez Palma | D30: 12500 | E30: =SUM(EDT!C98:C101) -> 18 | F30: =D30*E30 -> 225000 | H30: UTILIDAD | I30: =I26*I29 -> 11735306
A31: AP | B31: Analista Programador | C31: Javier Rodriguez | D31: 7340 | E31: =SUM(EDT!D98:D101) -> 42 | F31: =D31*E31 -> 308280 | H31: PRECIO FINAL | I31: =I26+I30 -> 31294150
A32: DBA | B32: Desarrollador BD | C32: Martin Guerrero | D32: 13278 | E32: =SUM(EDT!E98:E101) -> 36 | F32: =D32*E32 -> 478008
A33: QA | B33: Calidad Y Testing | C33: Allison Rubio | D33: 10944 | E33: =SUM(EDT!F98:F101) -> 68 | F33: =D33*E33 -> 744192
A34: DI | B34: Diseñador | C34: Sebastian Rojas | D34: 8444 | E34: =SUM(EDT!G98:G101) -> 0 | F34: =D34*E34 -> 0
B35: TOTAL FASE PRUEBAS QA | F35: =SUM(F30:F34) -> 1755480
A38: SIGLA | B38: ROL | C38: NOMBRE | D38: VALOR HORA HH | E38: HORAS | F38: FASE IMPLEMENTACION Y CIERRE
A39: JP | B39: Jefe de Proyecto | C39: Luis Gonzalez Palma | D39: 12500 | E39: =SUM(EDT!C103:C108) -> 34 | F39: =D39*E39 -> 425000
A40: AP | B40: Analista Programador | C40: Javier Rodriguez | D40: 7340 | E40: =SUM(EDT!D103:D108) -> 60 | F40: =D40*E40 -> 440400
A41: DBA | B41: Desarrollador BD | C41: Martin Guerrero | D41: 13278 | E41: =SUM(EDT!E103:E108) -> 36 | F41: =D41*E41 -> 478008
A42: QA | B42: Calidad Y Testing | C42: Allison Rubio | D42: 10944 | E42: =SUM(EDT!F103:F108) -> 40 | F42: =D42*E42 -> 437760
A43: DI | B43: Diseñador | C43: Sebastian Rojas | D43: 8444 | E43: =SUM(EDT!G103:G108) -> 8 | F43: =D43*E43 -> 67552
B44: TOTAL FASE IMPLEMENTACION | F44: =SUM(F39:F43) -> 1848720
